INFO:     Will watch for changes in these directories: ['/home/obushido/instaloader/instagram-telegram-bot/backend']
INFO:     Uvicorn running on http://0.0.0.0:8000 (Press CTRL+C to quit)
INFO:     Started reloader process [67902] using WatchFiles
Process SpawnProcess-1:
Traceback (most recent call last):
  File "/home/obushido/instaloader/instagram-telegram-bot/backend/venv/lib/python3.12/site-packages/sqlalchemy/engine/base.py", line 1961, in _exec_single_context
    self.dialect.do_execute(
  File "/home/obushido/instaloader/instagram-telegram-bot/backend/venv/lib/python3.12/site-packages/sqlalchemy/engine/default.py", line 944, in do_execute
    cursor.execute(statement, parameters)
sqlite3.OperationalError: no such table: instagramaccount

The above exception was the direct cause of the following exception:

Traceback (most recent call last):
  File "/usr/lib/python3.12/multiprocessing/process.py", line 314, in _bootstrap
    self.run()
  File "/usr/lib/python3.12/multiprocessing/process.py", line 108, in run
    self._target(*self._args, **self._kwargs)
  File "/home/obushido/instaloader/instagram-telegram-bot/backend/venv/lib/python3.12/site-packages/uvicorn/_subprocess.py", line 80, in subprocess_started
    target(sockets=sockets)
  File "/home/obushido/instaloader/instagram-telegram-bot/backend/venv/lib/python3.12/site-packages/uvicorn/server.py", line 65, in run
    return asyncio.run(self.serve(sockets=sockets))
           ^^^^^^^^^^^^^^^^^^^^^^^^^^^^^^^^^^^^^^^^
  File "/usr/lib/python3.12/asyncio/runners.py", line 194, in run
    return runner.run(main)
           ^^^^^^^^^^^^^^^^
  File "/usr/lib/python3.12/asyncio/runners.py", line 118, in run
    return self._loop.run_until_complete(task)
           ^^^^^^^^^^^^^^^^^^^^^^^^^^^^^^^^^^^
  File "uvloop/loop.pyx", line 1518, in uvloop.loop.Loop.run_until_complete
  File "/home/obushido/instaloader/instagram-telegram-bot/backend/venv/lib/python3.12/site-packages/uvicorn/server.py", line 69, in serve
    await self._serve(sockets)
  File "/home/obushido/instaloader/instagram-telegram-bot/backend/venv/lib/python3.12/site-packages/uvicorn/server.py", line 76, in _serve
    config.load()
  File "/home/obushido/instaloader/instagram-telegram-bot/backend/venv/lib/python3.12/site-packages/uvicorn/config.py", line 434, in load
    self.loaded_app = import_from_string(self.app)
                      ^^^^^^^^^^^^^^^^^^^^^^^^^^^^
  File "/home/obushido/instaloader/instagram-telegram-bot/backend/venv/lib/python3.12/site-packages/uvicorn/importer.py", line 19, in import_from_string
    module = importlib.import_module(module_str)
             ^^^^^^^^^^^^^^^^^^^^^^^^^^^^^^^^^^^
  File "/usr/lib/python3.12/importlib/__init__.py", line 90, in import_module
    return _bootstrap._gcd_import(name[level:], package, level)
           ^^^^^^^^^^^^^^^^^^^^^^^^^^^^^^^^^^^^^^^^^^^^^^^^^^^^
  File "<frozen importlib._bootstrap>", line 1387, in _gcd_import
  File "<frozen importlib._bootstrap>", line 1360, in _find_and_load
  File "<frozen importlib._bootstrap>", line 1331, in _find_and_load_unlocked
  File "<frozen importlib._bootstrap>", line 935, in _load_unlocked
  File "<frozen importlib._bootstrap_external>", line 995, in exec_module
  File "<frozen importlib._bootstrap>", line 488, in _call_with_frames_removed
  File "/home/obushido/instaloader/instagram-telegram-bot/backend/app/main.py", line 43, in <module>
    scheduler = TaskScheduler(BASE_URL)
                ^^^^^^^^^^^^^^^^^^^^^^^
  File "/home/obushido/instaloader/instagram-telegram-bot/backend/app/scheduler.py", line 15, in __init__
    self.scraper = InstagramScraper()
                   ^^^^^^^^^^^^^^^^^^
  File "/home/obushido/instaloader/instagram-telegram-bot/backend/app/scraper.py", line 35, in __init__
    self._init_session()
  File "/home/obushido/instaloader/instagram-telegram-bot/backend/app/scraper.py", line 41, in _init_session
    account = db_session.exec(
              ^^^^^^^^^^^^^^^^
  File "/home/obushido/instaloader/instagram-telegram-bot/backend/venv/lib/python3.12/site-packages/sqlmodel/orm/session.py", line 66, in exec
    results = super().execute(
              ^^^^^^^^^^^^^^^^
  File "/home/obushido/instaloader/instagram-telegram-bot/backend/venv/lib/python3.12/site-packages/sqlalchemy/orm/session.py", line 2365, in execute
    return self._execute_internal(
           ^^^^^^^^^^^^^^^^^^^^^^^
  File "/home/obushido/instaloader/instagram-telegram-bot/backend/venv/lib/python3.12/site-packages/sqlalchemy/orm/session.py", line 2251, in _execute_internal
    result: Result[Any] = compile_state_cls.orm_execute_statement(
                          ^^^^^^^^^^^^^^^^^^^^^^^^^^^^^^^^^^^^^^^^
  File "/home/obushido/instaloader/instagram-telegram-bot/backend/venv/lib/python3.12/site-packages/sqlalchemy/orm/context.py", line 306, in orm_execute_statement
    result = conn.execute(
             ^^^^^^^^^^^^^
  File "/home/obushido/instaloader/instagram-telegram-bot/backend/venv/lib/python3.12/site-packages/sqlalchemy/engine/base.py", line 1413, in execute
    return meth(
           ^^^^^
  File "/home/obushido/instaloader/instagram-telegram-bot/backend/venv/lib/python3.12/site-packages/sqlalchemy/sql/elements.py", line 526, in _execute_on_connection
    return connection._execute_clauseelement(
           ^^^^^^^^^^^^^^^^^^^^^^^^^^^^^^^^^^
  File "/home/obushido/instaloader/instagram-telegram-bot/backend/venv/lib/python3.12/site-packages/sqlalchemy/engine/base.py", line 1635, in _execute_clauseelement
    ret = self._execute_context(
          ^^^^^^^^^^^^^^^^^^^^^^
  File "/home/obushido/instaloader/instagram-telegram-bot/backend/venv/lib/python3.12/site-packages/sqlalchemy/engine/base.py", line 1840, in _execute_context
    return self._exec_single_context(
           ^^^^^^^^^^^^^^^^^^^^^^^^^^
  File "/home/obushido/instaloader/instagram-telegram-bot/backend/venv/lib/python3.12/site-packages/sqlalchemy/engine/base.py", line 1980, in _exec_single_context
    self._handle_dbapi_exception(
  File "/home/obushido/instaloader/instagram-telegram-bot/backend/venv/lib/python3.12/site-packages/sqlalchemy/engine/base.py", line 2349, in _handle_dbapi_exception
    raise sqlalchemy_exception.with_traceback(exc_info[2]) from e
  File "/home/obushido/instaloader/instagram-telegram-bot/backend/venv/lib/python3.12/site-packages/sqlalchemy/engine/base.py", line 1961, in _exec_single_context
    self.dialect.do_execute(
  File "/home/obushido/instaloader/instagram-telegram-bot/backend/venv/lib/python3.12/site-packages/sqlalchemy/engine/default.py", line 944, in do_execute
    cursor.execute(statement, parameters)
sqlalchemy.exc.OperationalError: (sqlite3.OperationalError) no such table: instagramaccount
[SQL: SELECT instagramaccount.id, instagramaccount.username, instagramaccount.password_hash, instagramaccount.session_file, instagramaccount.is_active, instagramaccount.last_login, instagramaccount.created_at, instagramaccount.updated_at 
FROM instagramaccount 
WHERE instagramaccount.is_active = 1]
(Background on this error at: https://sqlalche.me/e/20/e3q8)
INFO:     Stopping reloader process [67804]
